Workbook

Sheet Executive Summary
A1: Skyhigh SWG → Palo Alto Equivalency Analysis
A2: Source: 2026-07-21.backup (Skyhigh SWG 12.2.23 config export, dated 2026-07-17) — full gateway ruleset (gwrs.xml), 376 policy rules across 19 function areas.
A4: Metric | B4: Count
A5: Total policy rules analyzed | B5: 376
A6: Rules that actually BLOCK | B6: 72
A7: Rules that LOG ONLY (named as blocking, wired to continue) | B7: 116
A8: Rules that ALLOW (exit rule group early) | B8: 117
A9: Rules INACTIVE (disabled, or inside a disabled parent group) | B9: 23
A10: Function areas analyzed | B10: 19
A12: Headline findings
A13: 1. CRITICAL — HTTPS Scanning / Certificate Verification: every rule named "Block [certificate condition]" (self-signed, expired, revoked, unknown CA, untrusted CA, weak key exchange, unsafe signature algorithm) is wired to com.scur.mainaction.continue. None of them block. This is the identical governance failure pattern to Alert-All-SPG on the Palo Alto side — config that reads as enforcement and functions as logging.
A14: 2. Only 72 of 376 rules (19%) actually block anything. 117 (31%) are Allow-exits and 116 (31%) are log-only continues. The ruleset is, by volume, mostly exceptions and logging rather than enforcement.
A15: 3. Data Loss Prevention w/ICAP (response-direction/inbound DLP) — all 10 rules disabled. Confirms the prior equivalency work's inbound-DLP finding exactly, and there is no direct Palo Alto NGFW equivalent — closing this requires an Enterprise DLP subscription decision, not a rule port.
A16: 4. A rule group literally named "test - loginMSOverride" is live and enabled in the production ruleset. Flag for governance review before using this config as an equivalency baseline for anything cited externally.
A17: 5. URL Filter and Application Control are the most exception-heavy groups (81 and 50 rules respectively) with the widest spread of effective behaviors — both are better rebuilt clean on Palo Alto (App-ID + URL Filtering Profile) than ported rule-for-rule.

Sheet All Policy Rules
A1: All Policy Rules (376) — sortable/filterable source detail
A3: Function Area | B3: Rule Group Path | C3: Rule Name | D3: Rule Enabled | E3: Group Enabled Chain | F3: Effective Status | G3: Action ID | H3: Config ID | I3: Description
A4: Troubleshooting | B4: Troubleshooting | C4: Bypass source IP | D4: =TRUE() -> TRUE | E4: true | F4: OTHER: com.scur.mainaction.stopcycle | G4: com.scur.mainaction.stopcycle | I4: Bypass policy by source IP
A5: Troubleshooting | B5: Troubleshooting | C5: Bypass Domains in list Troubleshooting Domain Bypass | D5: =TRUE() -> TRUE | E5: true | F5: OTHER: com.scur.mainaction.stopcycle | G5: com.scur.mainaction.stopcycle
A6: test - loginMSOverride | B6: test - loginMSOverride | C6: HTTP2_byapss_login-microsoftonline | D6: =TRUE() -> TRUE | E6: true | F6: LOG-ONLY (continue) | G6: com.scur.mainaction.continue | I6: HTTP2_byapss_login.microsoftonline.com
A7: Common Rules | B7: Common Rules | C7: Categorize em All | D7: =TRUE() -> TRUE | E7: true | F7: LOG-ONLY (continue) | G7: com.scur.mainaction.continue | I7: Ensure categories show up in all log messages
A8: Common Rules | B8: Common Rules | C8: Enforce compression based on server response | D8: =TRUE() -> TRUE | E8: true | F8: LOG-ONLY (continue) | G8: com.scur.mainaction.continue
A9: Common Rules | B9: Common Rules > Http 1.1 | C9: Http 1.1 | D9: =TRUE() -> TRUE | E9: true,true | F9: LOG-ONLY (continue) | G9: com.scur.mainaction.continue | I9: Force specific IP's from 1.0 to 1.1 for konghq.com. Contact: Hanumanthaiah, MohanKumar <MohanKumar.H@CVSHealth.com>. We have identified that the response received from Proxy is HTTP /1.0 but Kong Gateway is expecting the response in HTTP/1.1 and Kong gateway doesn’t support HTTP/1.0 hence we are getting the bad request response.
A10: Common Rules | B10: Common Rules > Restrict CONNECT Ports | C10: Block Destination Ports for CONNECT: Blocked Ports | D10: =TRUE() -> TRUE | E10: true,true | F10: BLOCKING | G10: com.scur.mainaction.block | H10: com.scur.mainaction.block.17096 | I10: Blocks if url port is in list of blocked CONNECT ports.
A11: Common Rules | B11: Common Rules > Restrict CONNECT Ports | C11: Restrict Destination Port to Allowed CONNECT Ports | D11: =FALSE() -> FALSE | E11: true,true | F11: ALLOW (exits group) | G11: com.scur.mainaction.stoprulegroup | I11: Skip ruleset if it is allowed to CONNECT to Url.Port
A12: Common Rules | B12: Common Rules > Restrict CONNECT Ports | C12: Allow Sending Back HTTPS Block Page | D12: =TRUE() -> TRUE | E12: true,true | F12: LOG-ONLY (continue) | G12: com.scur.mainaction.continue
A13: Common Rules | B13: Common Rules > Restrict CONNECT Ports | C13: Restrict Destination Port to Allowed CONNECT Ports | D13: =FALSE() -> FALSE | E13: true,true | F13: BLOCKING | G13: com.scur.mainaction.block | H13: com.scur.mainaction.block.17096 | I13: Blocks URL ports that are not in list of allowed CONNECT ports.
A14: Common Rules | B14: Common Rules > Bandwidth Control | C14: Limit Downloads to 400mbps | D14: =TRUE() -> TRUE | E14: true,true | F14: ALLOW (exits group) | G14: com.scur.mainaction.stoprulegroup | I14: Limit Downloads using Bandwidth control classes
A15: Common Rules | B15: Common Rules > Bandwidth Control | C15: Limit Uploads to 300mbps | D15: =TRUE() -> TRUE | E15: true,true | F15: ALLOW (exits group) | G15: com.scur.mainaction.stoprulegroup | I15: Limit Uploads using Bandwidth control classes
A16: Common Rules | B16: Common Rules > LAB Only: AETHQ Proxy | C16: LAB Only: ProxxyGS | D16: =TRUE() -> TRUE | E16: true,false | F16: INACTIVE (disabled) | G16: com.scur.mainaction.stopcycle
A17: Common Rules | B17: Common Rules > LAB Only: AETHQ Proxy | C17: LAB Only: Forward traffic to AETHQ proxies | D17: =TRUE() -> TRUE | E17: true,false | F17: INACTIVE (disabled) | G17: com.scur.mainaction.continue
A18: Common Rules | B18: Common Rules > Forwarding | C18: Forward retprd.fisa.nycnet to VPN IP | D18: =TRUE() -> TRUE | E18: true,true | F18: LOG-ONLY (continue) | G18: com.scur.mainaction.continue
A19: Common Rules | B19: Common Rules > Forwarding | C19: Forward wmaccess.homeoffice.wal-mart.com to MPLS B2B IP | D19: =TRUE() -> TRUE | E19: true,true | F19: LOG-ONLY (continue) | G19: com.scur.mainaction.continue | I19: 8/21/18 - Still valid
A20: Common Rules | B20: Common Rules > Forwarding | C20: Forward concentrix wyse to NAT IP | D20: =TRUE() -> TRUE | E20: true,true | F20: LOG-ONLY (continue) | G20: com.scur.mainaction.continue | I20: ph4c3cvcs12v.concentrix.com - VMware Horizon web terminal redirected via NAT hosts file: 10.108.220.33 ph4c3cvcs12v.concentrix.com 8/21/2018 - Still valid
A21: Common Rules | B21: Common Rules > Forwarding | C21: Forward hsha.dpw.state.pa.us to hbgfire1 | D21: =TRUE() -> TRUE | E21: true,true | F21: LOG-ONLY (continue) | G21: com.scur.mainaction.continue | I21: 8/21/18 - Still valid
A22: Common Rules | B22: Common Rules > Forwarding | C22: Forward dpwintra.dpw.state.pa.us to hbgfire1 | D22: =TRUE() -> TRUE | E22: true,true | F22: LOG-ONLY (continue) | G22: com.scur.mainaction.continue | I22: 8/21/2018 Still valid
A23: Common Rules | B23: Common Rules > Forwarding | C23: Forward bswiftoutsysdev.com to MPLS IP in PDCHS | D23: =TRUE() -> TRUE | E23: true,true | F23: LOG-ONLY (continue) | G23: com.scur.mainaction.continue | I23: Forward bswiftoutsysdev.com to MPLS IP to bswift dev apps in PDCHS 08/21/2018 - still valid
A24: Common Rules | B24: Common Rules > Forwarding | C24: redirect carelink.chsli.org to VPN IP | D24: =TRUE() -> TRUE | E24: true,true | F24: LOG-ONLY (continue) | G24: com.scur.mainaction.continue | I24: CHG0333874 12/22/21 Catholic Health Services Long Island
A25: Common Rules | B25: Common Rules > Forwarding | C25: redirect ews1.chsli.org to VPN IP | D25: =TRUE() -> TRUE | E25: true,true | F25: LOG-ONLY (continue) | G25: com.scur.mainaction.continue | I25: CHG0333874 12/22/21 Catholic Health Services Long Island
A26: Common Rules | B26: Common Rules > CVS Redirects | C26: cvs.com domain redirects | D26: =FALSE() -> FALSE | E26: true,true | F26: REDIRECT | G26: com.scur.mainaction.redirect | H26: com.scur.mainaction.redirect.1655
A27: Common Rules | B27: Common Rules > CVS Redirects | C27: cvs.com domain redirects | D27: =FALSE() -> FALSE | E27: true,true | F27: REDIRECT | G27: com.scur.mainaction.redirect | H27: com.scur.mainaction.redirect.1583
A28: Common Rules | B28: Common Rules > CVS Redirects | C28: cvs.com domain redirects | D28: =FALSE() -> FALSE | E28: true,true | F28: REDIRECT | G28: com.scur.mainaction.redirect | H28: com.scur.mainaction.redirect.1584
A29: Common Rules | B29: Common Rules > CVS Redirects | C29: caremark.com domain redirects | D29: =TRUE() -> TRUE | E29: true,true | F29: REDIRECT | G29: com.scur.mainaction.redirect | H29: com.scur.mainaction.redirect.1616
A30: Common Rules | B30: Common Rules > Housekeeping | C30: F5 Health Check | D30: =TRUE() -> TRUE | E30: true,true | F30: OTHER: com.scur.mainaction.stopcycle | G30: com.scur.mainaction.stopcycle
A31: Common Rules | B31: Common Rules > Housekeeping | C31: Remove Via: Header | D31: =TRUE() -> TRUE | E31: true,true | F31: LOG-ONLY (continue) | G31: com.scur.mainaction.continue | I31: This rule removes the 'Via' header.
A32: Common Rules | B32: Common Rules > Housekeeping | C32: Remove X-Forwarded-For: Header | D32: =TRUE() -> TRUE | E32: true,true | F32: LOG-ONLY (continue) | G32: com.scur.mainaction.continue | I32: This rule removes the ' X-Forwarded-For' header.
A33: Common Rules | B33: Common Rules > Housekeeping | C33: Tag DMZ Clients | D33: =TRUE() -> TRUE | E33: true,true | F33: LOG-ONLY (continue) | G33: com.scur.mainaction.continue
A34: Common Rules | B34: Common Rules > Housekeeping | C34: Tag PCI Clients | D34: =TRUE() -> TRUE | E34: true,true | F34: LOG-ONLY (continue) | G34: com.scur.mainaction.continue
A35: Common Rules | B35: Common Rules > Housekeeping | C35: Tag Interoperability Encalve | D35: =TRUE() -> TRUE | E35: true,true | F35: LOG-ONLY (continue) | G35: com.scur.mainaction.continue
A36: Common Rules | B36: Common Rules > Housekeeping | C36: Allow Aetna DMZs | D36: =TRUE() -> TRUE | E36: true,true | F36: OTHER: com.scur.mainaction.stopcycle | G36: com.scur.mainaction.stopcycle
A37: Common Rules | B37: Common Rules > Housekeeping | C37: Allow Essential Domains | D37: =TRUE() -> TRUE | E37: true,true | F37: OTHER: com.scur.mainaction.stopcycle | G37: com.scur.mainaction.stopcycle
A38: Common Rules | B38: Common Rules > Housekeeping | C38: Bypass Firewall Managers from Proxy Checks | D38: =TRUE() -> TRUE | E38: true,true | F38: OTHER: com.scur.mainaction.stopcycle | G38: com.scur.mainaction.stopcycle
A39: Common Rules | B39: Common Rules > Housekeeping | C39: Blocked Hosts | D39: =TRUE() -> TRUE | E39: true,true | F39: BLOCKING | G39: com.scur.mainaction.block | H39: 20422
A40: Common Rules | B40: Common Rules > Housekeeping | C40: RegexBlock | D40: =TRUE() -> TRUE | E40: true,true | F40: BLOCKING | G40: com.scur.mainaction.block | H40: 20422
A41: Common Rules | B41: Common Rules > Housekeeping | C41: Block Proxy Names | D41: =TRUE() -> TRUE | E41: true,true | F41: BLOCKING | G41: com.scur.mainaction.block | H41: 20422 | I41: Prevent proxy looping
...

Sheet PA Deployment Recommendations
A1: Palo Alto Deployment Recommendations, by Function Area
A2: Rule counts below are computed live via COUNTIFS against the 'All Policy Rules' tab.
A4: Function Area | B4: Rule Count | C4: Blocking | D4: Log-Only | E4: Allow-Exit | F4: Disabled | G4: PA Equivalent Construct | H4: Deployment Recommendation | I4: Priority
A5: URL Filter | B5: =COUNTIF('All Policy Rules'!A:A,A5) -> 81 | C5: =COUNTIFS('All Policy Rules'!A:A,A5,'All Policy Rules'!F:F,"BLOCKING") -> 20 | D5: =COUNTIFS('All Policy Rules'!A:A,A5,'All Policy Rules'!F:F,"LOG-ONLY (continue)") -> 11 | E5: =COUNTIFS('All Policy Rules'!A:A,A5,'All Policy Rules'!F:F,"ALLOW (exits group)") -> 44 | F5: =COUNTIFS('All Policy Rules'!A:A,A5,'All Policy Rules'!F:F,"INACTIVE (disabled)") -> 4 | G5: URL Filtering Profile (PAN-DB categories) + custom URL categories | H5: Largest single group (81 rules) and the most exception-heavy: 44 Allow-exits vs. only 20 actual blocks, plus 11 log-only and 4 disabled. This reads as years of accumulated one-off exceptions layered on top of a base policy. Recommend a clean-slate URL Filtering Profile built from PAN-DB categories plus a short, deliberately maintained custom-category allowlist — not a port of the current exception sprawl, which would carry the sprawl's maintenance burden into the new platform. | I5: High
A6: Common Rules | B6: =COUNTIF('All Policy Rules'!A:A,A6) -> 60 | C6: =COUNTIFS('All Policy Rules'!A:A,A6,'All Policy Rules'!F:F,"BLOCKING") -> 9 | D6: =COUNTIFS('All Policy Rules'!A:A,A6,'All Policy Rules'!F:F,"LOG-ONLY (continue)") -> 31 | E6: =COUNTIFS('All Policy Rules'!A:A,A6,'All Policy Rules'!F:F,"ALLOW (exits group)") -> 6 | F6: =COUNTIFS('All Policy Rules'!A:A,A6,'All Policy Rules'!F:F,"INACTIVE (disabled)") -> 2 | G6: Security Policy base rulebase / rule-ordering foundation | H6: Shared logic underpinning other groups. Roughly half of these rules are log-only. Translate into the PA rulebase's ordering and default-deny structure rather than as a literal 1:1 rule port — Common Rules exists to compensate for McAfee's first-match linear rule evaluation model, which PA's zone/App-ID model doesn't need in the same shape. | I6: Medium
A7: HTTPS Scanning | B7: =COUNTIF('All Policy Rules'!A:A,A7) -> 54 | C7: =COUNTIFS('All Policy Rules'!A:A,A7,'All Policy Rules'!F:F,"BLOCKING") -> 11 | D7: =COUNTIFS('All Policy Rules'!A:A,A7,'All Policy Rules'!F:F,"LOG-ONLY (continue)") -> 14 | E7: =COUNTIFS('All Policy Rules'!A:A,A7,'All Policy Rules'!F:F,"ALLOW (exits group)") -> 26 | F7: =COUNTIFS('All Policy Rules'!A:A,A7,'All Policy Rules'!F:F,"INACTIVE (disabled)") -> 0 | G7: Decryption Profile (SSL Forward Proxy) — certificate validation checks | H7: THE headline finding of this analysis. Every rule named "Block [certificate condition]" in this group is wired to com.scur.mainaction.continue — it logs and passes the connection, never blocks. Only 11 of 54 rules in this group actually block; 14 are silently log-only including every certificate-validation check; 26 are bypass/allow exits. When this is rebuilt in Palo Alto's Decryption Profile, the equivalent checkboxes ("Block sessions with expired/untrusted/unsupported cert", "Block sessions on SSL/TLS errors") must be explicitly enabled — do not port the current McAfee behavior as the baseline, since the current behavior is not what its own rule names claim it is. | I7: CRITICAL
A8: Application Control | B8: =COUNTIF('All Policy Rules'!A:A,A8) -> 50 | C8: =COUNTIFS('All Policy Rules'!A:A,A8,'All Policy Rules'!F:F,"BLOCKING") -> 12 | D8: =COUNTIFS('All Policy Rules'!A:A,A8,'All Policy Rules'!F:F,"LOG-ONLY (continue)") -> 10 | E8: =COUNTIFS('All Policy Rules'!A:A,A8,'All Policy Rules'!F:F,"ALLOW (exits group)") -> 12 | F8: =COUNTIFS('All Policy Rules'!A:A,A8,'All Policy Rules'!F:F,"INACTIVE (disabled)") -> 6 | G8: App-ID enforcement in the Security Policy rulebase | H8: Genuinely mixed enforcement: 12 blocking, 12 allow-exit, 10 log-only, 6 disabled, 5 "remove" actions, 1 stopcycle — six different effective behaviors in one group of 50 rules. Do not port this structure as-is. Rebuild as an App-ID-based rulebase with a small number of explicit allow/deny rules per application category; the current group's complexity is itself the finding. | I8: High
A9: Agentless notifications | B9: =COUNTIF('All Policy Rules'!A:A,A9) -> 23 | C9: =COUNTIFS('All Policy Rules'!A:A,A9,'All Policy Rules'!F:F,"BLOCKING") -> 0 | D9: =COUNTIFS('All Policy Rules'!A:A,A9,'All Policy Rules'!F:F,"LOG-ONLY (continue)") -> 22 | E9: =COUNTIFS('All Policy Rules'!A:A,A9,'All Policy Rules'!F:F,"ALLOW (exits group)") -> 1 | F9: =COUNTIFS('All Policy Rules'!A:A,A9,'All Policy Rules'!F:F,"INACTIVE (disabled)") -> 0 | G9: Response Pages / Captive Portal notification banners | H9: 22 of 23 rules are log-only by design — this group appears intended purely for notification/logging, not enforcement. Map to PA response pages for the equivalent user-facing notifications; no blocking behavior to preserve. | I9: Low
A10: Data Loss Prevention (DLP) | B10: =COUNTIF('All Policy Rules'!A:A,A10) -> 23 | C10: =COUNTIFS('All Policy Rules'!A:A,A10,'All Policy Rules'!F:F,"BLOCKING") -> 6 | D10: =COUNTIFS('All Policy Rules'!A:A,A10,'All Policy Rules'!F:F,"LOG-ONLY (continue)") -> 15 | E10: =COUNTIFS('All Policy Rules'!A:A,A10,'All Policy Rules'!F:F,"ALLOW (exits group)") -> 1 | F10: =COUNTIFS('All Policy Rules'!A:A,A10,'All Policy Rules'!F:F,"INACTIVE (disabled)") -> 1 | G10: Data Filtering Profile (predefined + custom Data Patterns) attached to Security Policy | H10: Only 6 of 22 active rules actually block; 15 are log-only, 1 disabled. The dictionaries behind this group (CVS Health SSN, HICN, Member ID, GEMS ID, PCI patterns) are real and detailed — port those definitions directly into PA Data Patterns (regex/predefined-pattern equivalents exist for SSN and PAN; HICN and the CVS-specific IDs need custom regex objects). This is the same estate NETSEC-DLP-01 is already scoping — coordinate rather than duplicate. | I10: High
A11: Gateway Anti-Malware | B11: =COUNTIF('All Policy Rules'!A:A,A11) -> 19 | C11: =COUNTIFS('All Policy Rules'!A:A,A11,'All Policy Rules'!F:F,"BLOCKING") -> 9 | D11: =COUNTIFS('All Policy Rules'!A:A,A11,'All Policy Rules'!F:F,"LOG-ONLY (continue)") -> 4 | E11: =COUNTIFS('All Policy Rules'!A:A,A11,'All Policy Rules'!F:F,"ALLOW (exits group)") -> 6 | F11: =COUNTIFS('All Policy Rules'!A:A,A11,'All Policy Rules'!F:F,"INACTIVE (disabled)") -> 0 | G11: Antivirus Profile + WildFire Analysis Profile | H11: The healthiest group in this config: 9 blocking, 4 log-only, 6 allow-exit, 0 disabled. Map fairly directly to an Antivirus Profile (signature-based) plus WildFire (unknown-file sandboxing) attached across zones — closest thing here to a genuine like-for-like port. | I11: Medium
A12: Bypass Microsoft (Office 365) Services | B12: =COUNTIF('All Policy Rules'!A:A,A12) -> 15 | C12: =COUNTIFS('All Policy Rules'!A:A,A12,'All Policy Rules'!F:F,"BLOCKING") -> 0 | D12: =COUNTIFS('All Policy Rules'!A:A,A12,'All Policy Rules'!F:F,"LOG-ONLY (continue)") -> 0 | E12: =COUNTIFS('All Policy Rules'!A:A,A12,'All Policy Rules'!F:F,"ALLOW (exits group)") -> 2 | F12: =COUNTIFS('All Policy Rules'!A:A,A12,'All Policy Rules'!F:F,"INACTIVE (disabled)") -> 0 | G12: Decryption Policy exclusion using the predefined "Microsoft 365" EDL / URL category | H12: All 15 rules here are either Allow-exit or Redirect — none block. Replace the manually maintained bypass list with PA's built-in Microsoft 365 URL category / EDL, which Palo Alto maintains and updates centrally — avoids the maintenance burden this custom list currently carries. | I12: Medium
A13: Authentication | B13: =COUNTIF('All Policy Rules'!A:A,A13) -> 13 | C13: =COUNTIFS('All Policy Rules'!A:A,A13,'All Policy Rules'!F:F,"BLOCKING") -> 0 | D13: =COUNTIFS('All Policy Rules'!A:A,A13,'All Policy Rules'!F:F,"LOG-ONLY (continue)") -> 0 | E13: =COUNTIFS('All Policy Rules'!A:A,A13,'All Policy Rules'!F:F,"ALLOW (exits group)") -> 12 | F13: =COUNTIFS('All Policy Rules'!A:A,A13,'All Policy Rules'!F:F,"INACTIVE (disabled)") -> 0 | G13: Authentication Policy + Authentication Profile / User-ID | H13: 12 of 13 rules exit via Allow — this group is structured mostly as an exception/passthrough list around a single real auth challenge. Map the one AUTH-CHALLENGE rule to a PA Authentication Policy rule tied to an Authentication Profile (SAML/Kerberos/NTLM per current IdP), and rebuild the 12 exceptions as an explicit no-auth-required Security Policy rule rather than leaving them implicit in evaluation order. | I13: Medium
A14: Data Loss Prevention w/ICAP | B14: =COUNTIF('All Policy Rules'!A:A,A14) -> 10 | C14: =COUNTIFS('All Policy Rules'!A:A,A14,'All Policy Rules'!F:F,"BLOCKING") -> 0 | D14: =COUNTIFS('All Policy Rules'!A:A,A14,'All Policy Rules'!F:F,"LOG-ONLY (continue)") -> 0 | E14: =COUNTIFS('All Policy Rules'!A:A,A14,'All Policy Rules'!F:F,"ALLOW (exits group)") -> 0 | F14: =COUNTIFS('All Policy Rules'!A:A,A14,'All Policy Rules'!F:F,"INACTIVE (disabled)") -> 10 | G14: No native equivalent — requires Palo Alto Enterprise DLP (cloud subscription) for response-direction/inbound inspection | H14: All 10 rules are disabled — this is the same inbound/response-cycle gap the original Skyhigh equivalency work already flagged. Palo Alto NGFW does not have a direct ICAP-response-DLP equivalent; closing this gap on Palo Alto requires evaluating the Enterprise DLP subscription rather than a like-for-like policy port. Flag as a licensing/architecture decision, not a rule-migration task. | I14: High (strategic)
A15: Internal Sites | B15: =COUNTIF('All Policy Rules'!A:A,A15) -> 6 | C15: =COUNTIFS('All Policy Rules'!A:A,A15,'All Policy Rules'!F:F,"BLOCKING") -> 2 | D15: =COUNTIFS('All Policy Rules'!A:A,A15,'All Policy Rules'!F:F,"LOG-ONLY (continue)") -> 1 | E15: =COUNTIFS('All Policy Rules'!A:A,A15,'All Policy Rules'!F:F,"ALLOW (exits group)") -> 0 | F15: =COUNTIFS('All Policy Rules'!A:A,A15,'All Policy Rules'!F:F,"INACTIVE (disabled)") -> 0 | G15: Security Policy (internal zone match) + SSL Decryption Policy exclusion | H15: Port the internal site list into a PA Address Object / EDL referenced by both a Security Policy allow rule and a Decryption Policy no-decrypt rule, rather than duplicating the list in two places. | I15: Medium
A16: Enable Opener | B16: =COUNTIF('All Policy Rules'!A:A,A16) -> 5 | C16: =COUNTIFS('All Policy Rules'!A:A,A16,'All Policy Rules'!F:F,"BLOCKING") -> 3 | D16: =COUNTIFS('All Policy Rules'!A:A,A16,'All Policy Rules'!F:F,"LOG-ONLY (continue)") -> 1 | E16: =COUNTIFS('All Policy Rules'!A:A,A16,'All Policy Rules'!F:F,"ALLOW (exits group)") -> 1 | F16: =COUNTIFS('All Policy Rules'!A:A,A16,'All Policy Rules'!F:F,"INACTIVE (disabled)") -> 0 | G16: File Blocking Profile + WildFire (archive/container extraction) | H16: Small group (5 rules). Map archive-opening behavior to WildFire's file-type and archive inspection settings in a File Blocking Profile. | I16: Low-Medium
... A23: Timeout Extension | B23: =COUNTIF('All Policy Rules'!A:A,A23) -> 1 | C23: =COUNTIFS('All Policy Rules'!A:A,A23,'All Policy Rules'!F:F,"BLOCKING") -> 0 | D23: =COUNTIFS('All Policy Rules'!A:A,A23,'All Policy Rules'!F:F,"LOG-ONLY (continue)") -> 1 | E23: =COUNTIFS('All Policy Rules'!A:A,A23,'All Policy Rules'!F:F,"ALLOW (exits group)") -> 0 | F23: =COUNTIFS('All Policy Rules'!A:A,A23,'All Policy Rules'!F:F,"INACTIVE (disabled)") -> 0 | G23: N/A — session/timeout configuration, not a security policy | H23: Configure directly in PA session settings if a specific timeout requirement exists; not a rulebase item. | I23: Low

Sheet Error Handlers (context)
A1: Error Handlers (context)
A2: Block/error page behavior — operational/cosmetic, not security enforcement. Listed for completeness; no direct 1:1 Palo Alto rule mapping (PA response pages serve this role).
A4: Handler Name | B4: Handler Enabled | C4: Rule Name | D4: Rule Enabled
A5: default | B5: true | C5: AM-Engine | D5: true
A6: default | B6: true | C6: AM-Proactive | D6: true
A7: default | B7: true | C7: AM-Signature | D7: true
A8: default | B8: true | C8: Avira-Engine | D8: true
A9: default | B9: true | C9: Avira-Savapi | D9: true
A10: default | B10: true | C10: Avira-VDF | D10: true
A11: default | B11: true | C11: MFE-DAT | D11: true
A12: default | B12: true | C12: MFE-Engine | D12: true
A13: default | B13: true | C13: TS-Database | D13: true
A14: default | B14: true | C14: TS-Engine | D14: true
A15: default | B15: true | C15: Create Event Message | D15: true
... A121: default | B121: true | C121: Always Block | D121: true

Sheet Log Handlers (context)
A1: Log Handlers (context)
A2: Logging format/destination rules — operational, not security enforcement. Listed for completeness.
A4: Handler Name | B4: Handler Enabled | C4: Rule Name | D4: Rule Enabled
A5: Logging | B5: true | C5: Ignore 407 Negotiation | D5: true
A6: Logging | B6: true | C6: Skip F5 Health Check | D6: true
A7: Logging | B7: true | C7: Skip Proxy Utility Access | D7: true
A8: Logging | B8: true | C8: Set Error Msg for Auth Failures | D8: true
A9: Logging | B9: true | C9: Clear Invalid 407 UserName | D9: true
A10: Logging | B10: true | C10: Set GTI Cloud Lookup Status | D10: true
A11: Logging | B11: true | C11: Set Malware.Name | D11: true
A12: Logging | B12: true | C12: Append Antimalware.VirusNames | D12: true
A13: Logging | B13: true | C13: Append AllowGroups | D13: true
A14: Logging | B14: true | C14: Embedded Objects Alert | D14: true
A15: Logging | B15: true | C15: Escape URL Path, Parameters and Ext | D15: true
... A25: Logging | B25: true | C25: Write GemsID log | D25: true
